Workbook

Sheet Assumptions
A1: Mobile Money & Airtime Kiosk — Daily Transactions Model (5 Years)
A2: All monetary values in Ugandan Shillings (UGX). Blue cells are editable inputs; black cells are calculated.
A4: 1. SIMULATION PERIOD
A5: Start date | B5: 46023
A6: End date | B6: 47848
A7: Number of days simulated | B7: =B6-B5+1 -> 1826
A9: 2. INITIAL (STARTUP) CAPITAL
A10: Float capital (mobile money agent line) | B10: 3000000
A11: Initial airtime / data bundle stock | B11: 500000
A12: Kiosk setup (structure, signage, stool, umbrella) | B12: 800000
A13: Rent deposit (advance) | B13: 300000
A14: Equipment (phone, register book, solar charger, POS) | B14: 400000
A15: TOTAL INITIAL INVESTMENT (Starting Capital) | B15: =SUM(B10:B14) -> 5000000
A17: 3. MOBILE MONEY REVENUE DRIVERS
A18: Starting mobile money transactions / month (baseline) | B18: 500 | C18: Forecast given in the scenario
A19: Equivalent starting MM transactions / day | B19: =B18/30.44 -> 16.425756 | C19: Baseline month figure spread over an average 30.44-day month
A20: Monthly transaction growth rate — Year 1 | B20: 0.02
A21: Monthly transaction growth rate — Year 2 onward | B21: 0.005
A22: Equivalent daily growth rate — Year 1 | B22: =(1+B20)^(1/30.44)-1 -> 0.00065075788 | C22: (1+monthly rate)^(1/30.44) - 1
A23: Equivalent daily growth rate — Year 2 onward | B23: =(1+B21)^(1/30.44)-1 -> 0.0001638617
A24: Average commission earned per transaction (UGX) | B24: 600
A26: 4. AIRTIME / DATA BUNDLE REVENUE DRIVERS
A27: Starting airtime/data transactions / month (baseline) | B27: 400
A28: Equivalent starting airtime transactions / day | B28: =B27/30.44 -> 13.140604
A29: Monthly airtime transaction growth rate | B29: 0.01
A30: Equivalent daily airtime growth rate | B30: =(1+B29)^(1/30.44)-1 -> 0.00032693684
A31: Average markup profit per airtime/data sale (UGX) | B31: 300
A33: 5. DAY-OF-WEEK EFFECT
A34: Weekend transaction multiplier (Sat & Sun) | B34: 0.6 | C34: Kiosk clientele is students/staff, so weekend footfall is lighter
A35: Weekday transaction multiplier (Mon-Fri) | B35: 1
A37: 6. MONTHLY OPERATING COSTS (booked on the 1st of each calendar month)
A38: Kiosk rent | B38: 150000
A39: Transport for float top-up | B39: 40000
A40: Agent line / mobile money service charges | B40: 30000
A41: Utilities (phone charging, lighting) | B41: 20000
A42: Attendant wage (starts calendar Month 13) | B42: 150000
A43: Miscellaneous / contingency | B43: 20000
A45: 7. OTHER
A46: Monthly cost inflation (applied from calendar Month 13) | B46: 0.003

Sheet Daily Ledger
A1: Day # | B1: Date | C1: Sim Year | D1: Calendar Month # | E1: Day of Week | F1: Weekday Multiplier | G1: Cost Inflation Factor | H1: MM Transactions (trend) | I1: MM Transactions (actual) | J1: Commission Revenue | K1: Airtime Transactions (trend) | L1: Airtime Transactions (actual) | M1: Airtime Revenue | N1: Total Daily Revenue | O1: Rent | P1: Transport | Q1: Agent Charges | R1: Utilities | S1: Wage | T1: Misc | U1: Total Daily Costs | V1: Net Daily Profit | W1: Cumulative Net Cash Position | X1: Breakeven Reached?
A2: 1 | B2: =Assumptions!B5 -> 46023 | C2: =MIN(ROUNDUP(A2/365,0),5) -> 1 | D2: =DATEDIF(Assumptions!B5,B2,"m")+1 -> 1 | E2: =TEXT(B2,"ddd") -> Thu | F2: =IF(WEEKDAY(B2,2)>=6,Assumptions!B34,Assumptions!B35) -> 1 | G2: =IF(D2>=13,(1+Assumptions!B46)^(D2-12),1) -> 1 | H2: =Assumptions!B19 -> 16.425756 | I2: =ROUND(H2*F2,0) -> 16 | J2: =I2*Assumptions!B24 -> 9600 | K2: =Assumptions!B28 -> 13.140604 | L2: =ROUND(K2*F2,0) -> 13 | M2: =L2*Assumptions!B31 -> 3900 | N2: =J2+M2 -> 13500 | O2: =IF(DAY(B2)=1,Assumptions!B38*G2,0) -> 150000 | P2: =IF(DAY(B2)=1,Assumptions!B39*G2,0) -> 40000 | Q2: =IF(DAY(B2)=1,Assumptions!B40*G2,0) -> 30000 | R2: =IF(DAY(B2)=1,Assumptions!B41*G2,0) -> 20000 | S2: =IF(AND(DAY(B2)=1,D2>=13),Assumptions!B42*G2,0) -> 0 | T2: =IF(DAY(B2)=1,Assumptions!B43*G2,0) -> 20000 | U2: =SUM(O2:T2) -> 260000 | V2: =N2-U2 -> -246500 | W2: =-Assumptions!B15+V2 -> -5246500 | X2: =IF(W2>=0,"YES","No") -> No
A3: 2 | B3: =B2+1 -> 46024 | C3: =MIN(ROUNDUP(A3/365,0),5) -> 1 | D3: =DATEDIF(Assumptions!B5,B3,"m")+1 -> 1 | E3: =TEXT(B3,"ddd") -> Fri | F3: =IF(WEEKDAY(B3,2)>=6,Assumptions!B34,Assumptions!B35) -> 1 | G3: =IF(D3>=13,(1+Assumptions!B46)^(D3-12),1) -> 1 | H3: =H2*(1+IF(C3=1,Assumptions!B22,Assumptions!B23)) -> 16.436445 | I3: =ROUND(H3*F3,0) -> 16 | J3: =I3*Assumptions!B24 -> 9600 | K3: =K2*(1+Assumptions!B30) -> 13.144901 | L3: =ROUND(K3*F3,0) -> 13 | M3: =L3*Assumptions!B31 -> 3900 | N3: =J3+M3 -> 13500 | O3: =IF(DAY(B3)=1,Assumptions!B38*G3,0) -> 0 | P3: =IF(DAY(B3)=1,Assumptions!B39*G3,0) -> 0 | Q3: =IF(DAY(B3)=1,Assumptions!B40*G3,0) -> 0 | R3: =IF(DAY(B3)=1,Assumptions!B41*G3,0) -> 0 | S3: =IF(AND(DAY(B3)=1,D3>=13),Assumptions!B42*G3,0) -> 0 | T3: =IF(DAY(B3)=1,Assumptions!B43*G3,0) -> 0 | U3: =SUM(O3:T3) -> 0 | V3: =N3-U3 -> 13500 | W3: =W2+V3 -> -5233000 | X3: =IF(W3>=0,"YES","No") -> No
A4: 3 | B4: =B3+1 -> 46025 | C4: =MIN(ROUNDUP(A4/365,0),5) -> 1 | D4: =DATEDIF(Assumptions!B5,B4,"m")+1 -> 1 | E4: =TEXT(B4,"ddd") -> Sat | F4: =IF(WEEKDAY(B4,2)>=6,Assumptions!B34,Assumptions!B35) -> 0.6 | G4: =IF(D4>=13,(1+Assumptions!B46)^(D4-12),1) -> 1 | H4: =H3*(1+IF(C4=1,Assumptions!B22,Assumptions!B23)) -> 16.447141 | I4: =ROUND(H4*F4,0) -> 10 | J4: =I4*Assumptions!B24 -> 6000 | K4: =K3*(1+Assumptions!B30) -> 13.149198 | L4: =ROUND(K4*F4,0) -> 8 | M4: =L4*Assumptions!B31 -> 2400 | N4: =J4+M4 -> 8400 | O4: =IF(DAY(B4)=1,Assumptions!B38*G4,0) -> 0 | P4: =IF(DAY(B4)=1,Assumptions!B39*G4,0) -> 0 | Q4: =IF(DAY(B4)=1,Assumptions!B40*G4,0) -> 0 | R4: =IF(DAY(B4)=1,Assumptions!B41*G4,0) -> 0 | S4: =IF(AND(DAY(B4)=1,D4>=13),Assumptions!B42*G4,0) -> 0 | T4: =IF(DAY(B4)=1,Assumptions!B43*G4,0) -> 0 | U4: =SUM(O4:T4) -> 0 | V4: =N4-U4 -> 8400 | W4: =W3+V4 -> -5224600 | X4: =IF(W4>=0,"YES","No") -> No
A5: 4 | B5: =B4+1 -> 46026 | C5: =MIN(ROUNDUP(A5/365,0),5) -> 1 | D5: =DATEDIF(Assumptions!B5,B5,"m")+1 -> 1 | E5: =TEXT(B5,"ddd") -> Sun | F5: =IF(WEEKDAY(B5,2)>=6,Assumptions!B34,Assumptions!B35) -> 0.6 | G5: =IF(D5>=13,(1+Assumptions!B46)^(D5-12),1) -> 1 | H5: =H4*(1+IF(C5=1,Assumptions!B22,Assumptions!B23)) -> 16.457844 | I5: =ROUND(H5*F5,0) -> 10 | J5: =I5*Assumptions!B24 -> 6000 | K5: =K4*(1+Assumptions!B30) -> 13.153497 | L5: =ROUND(K5*F5,0) -> 8 | M5: =L5*Assumptions!B31 -> 2400 | N5: =J5+M5 -> 8400 | O5: =IF(DAY(B5)=1,Assumptions!B38*G5,0) -> 0 | P5: =IF(DAY(B5)=1,Assumptions!B39*G5,0) -> 0 | Q5: =IF(DAY(B5)=1,Assumptions!B40*G5,0) -> 0 | R5: =IF(DAY(B5)=1,Assumptions!B41*G5,0) -> 0 | S5: =IF(AND(DAY(B5)=1,D5>=13),Assumptions!B42*G5,0) -> 0 | T5: =IF(DAY(B5)=1,Assumptions!B43*G5,0) -> 0 | U5: =SUM(O5:T5) -> 0 | V5: =N5-U5 -> 8400 | W5: =W4+V5 -> -5216200 | X5: =IF(W5>=0,"YES","No") -> No
A6: 5 | B6: =B5+1 -> 46027 | C6: =MIN(ROUNDUP(A6/365,0),5) -> 1 | D6: =DATEDIF(Assumptions!B5,B6,"m")+1 -> 1 | E6: =TEXT(B6,"ddd") -> Mon | F6: =IF(WEEKDAY(B6,2)>=6,Assumptions!B34,Assumptions!B35) -> 1 | G6: =IF(D6>=13,(1+Assumptions!B46)^(D6-12),1) -> 1 | H6: =H5*(1+IF(C6=1,Assumptions!B22,Assumptions!B23)) -> 16.468554 | I6: =ROUND(H6*F6,0) -> 16 | J6: =I6*Assumptions!B24 -> 9600 | K6: =K5*(1+Assumptions!B30) -> 13.157797 | L6: =ROUND(K6*F6,0) -> 13 | M6: =L6*Assumptions!B31 -> 3900 | N6: =J6+M6 -> 13500 | O6: =IF(DAY(B6)=1,Assumptions!B38*G6,0) -> 0 | P6: =IF(DAY(B6)=1,Assumptions!B39*G6,0) -> 0 | Q6: =IF(DAY(B6)=1,Assumptions!B40*G6,0) -> 0 | R6: =IF(DAY(B6)=1,Assumptions!B41*G6,0) -> 0 | S6: =IF(AND(DAY(B6)=1,D6>=13),Assumptions!B42*G6,0) -> 0 | T6: =IF(DAY(B6)=1,Assumptions!B43*G6,0) -> 0 | U6: =SUM(O6:T6) -> 0 | V6: =N6-U6 -> 13500 | W6: =W5+V6 -> -5202700 | X6: =IF(W6>=0,"YES","No") -> No
A7: 6 | B7: =B6+1 -> 46028 | C7: =MIN(ROUNDUP(A7/365,0),5) -> 1 | D7: =DATEDIF(Assumptions!B5,B7,"m")+1 -> 1 | E7: =TEXT(B7,"ddd") -> Tue | F7: =IF(WEEKDAY(B7,2)>=6,Assumptions!B34,Assumptions!B35) -> 1 | G7: =IF(D7>=13,(1+Assumptions!B46)^(D7-12),1) -> 1 | H7: =H6*(1+IF(C7=1,Assumptions!B22,Assumptions!B23)) -> 16.479271 | I7: =ROUND(H7*F7,0) -> 16 | J7: =I7*Assumptions!B24 -> 9600 | K7: =K6*(1+Assumptions!B30) -> 13.162099 | L7: =ROUND(K7*F7,0) -> 13 | M7: =L7*Assumptions!B31 -> 3900 | N7: =J7+M7 -> 13500 | O7: =IF(DAY(B7)=1,Assumptions!B38*G7,0) -> 0 | P7: =IF(DAY(B7)=1,Assumptions!B39*G7,0) -> 0 | Q7: =IF(DAY(B7)=1,Assumptions!B40*G7,0) -> 0 | R7: =IF(DAY(B7)=1,Assumptions!B41*G7,0) -> 0 | S7: =IF(AND(DAY(B7)=1,D7>=13),Assumptions!B42*G7,0) -> 0 | T7: =IF(DAY(B7)=1,Assumptions!B43*G7,0) -> 0 | U7: =SUM(O7:T7) -> 0 | V7: =N7-U7 -> 13500 | W7: =W6+V7 -> -5189200 | X7: =IF(W7>=0,"YES","No") -> No
A8: 7 | B8: =B7+1 -> 46029 | C8: =MIN(ROUNDUP(A8/365,0),5) -> 1 | D8: =DATEDIF(Assumptions!B5,B8,"m")+1 -> 1 | E8: =TEXT(B8,"ddd") -> Wed | F8: =IF(WEEKDAY(B8,2)>=6,Assumptions!B34,Assumptions!B35) -> 1 | G8: =IF(D8>=13,(1+Assumptions!B46)^(D8-12),1) -> 1 | H8: =H7*(1+IF(C8=1,Assumptions!B22,Assumptions!B23)) -> 16.489995 | I8: =ROUND(H8*F8,0) -> 16 | J8: =I8*Assumptions!B24 -> 9600 | K8: =K7*(1+Assumptions!B30) -> 13.166402 | L8: =ROUND(K8*F8,0) -> 13 | M8: =L8*Assumptions!B31 -> 3900 | N8: =J8+M8 -> 13500 | O8: =IF(DAY(B8)=1,Assumptions!B38*G8,0) -> 0 | P8: =IF(DAY(B8)=1,Assumptions!B39*G8,0) -> 0 | Q8: =IF(DAY(B8)=1,Assumptions!B40*G8,0) -> 0 | R8: =IF(DAY(B8)=1,Assumptions!B41*G8,0) -> 0 | S8: =IF(AND(DAY(B8)=1,D8>=13),Assumptions!B42*G8,0) -> 0 | T8: =IF(DAY(B8)=1,Assumptions!B43*G8,0) -> 0 | U8: =SUM(O8:T8) -> 0 | V8: =N8-U8 -> 13500 | W8: =W7+V8 -> -5175700 | X8: =IF(W8>=0,"YES","No") -> No
A9: 8 | B9: =B8+1 -> 46030 | C9: =MIN(ROUNDUP(A9/365,0),5) -> 1 | D9: =DATEDIF(Assumptions!B5,B9,"m")+1 -> 1 | E9: =TEXT(B9,"ddd") -> Thu | F9: =IF(WEEKDAY(B9,2)>=6,Assumptions!B34,Assumptions!B35) -> 1 | G9: =IF(D9>=13,(1+Assumptions!B46)^(D9-12),1) -> 1 | H9: =H8*(1+IF(C9=1,Assumptions!B22,Assumptions!B23)) -> 16.500726 | I9: =ROUND(H9*F9,0) -> 17 | J9: =I9*Assumptions!B24 -> 10200 | K9: =K8*(1+Assumptions!B30) -> 13.170707 | L9: =ROUND(K9*F9,0) -> 13 | M9: =L9*Assumptions!B31 -> 3900 | N9: =J9+M9 -> 14100 | O9: =IF(DAY(B9)=1,Assumptions!B38*G9,0) -> 0 | P9: =IF(DAY(B9)=1,Assumptions!B39*G9,0) -> 0 | Q9: =IF(DAY(B9)=1,Assumptions!B40*G9,0) -> 0 | R9: =IF(DAY(B9)=1,Assumptions!B41*G9,0) -> 0 | S9: =IF(AND(DAY(B9)=1,D9>=13),Assumptions!B42*G9,0) -> 0 | T9: =IF(DAY(B9)=1,Assumptions!B43*G9,0) -> 0 | U9: =SUM(O9:T9) -> 0 | V9: =N9-U9 -> 14100 | W9: =W8+V9 -> -5161600 | X9: =IF(W9>=0,"YES","No") -> No
A10: 9 | B10: =B9+1 -> 46031 | C10: =MIN(ROUNDUP(A10/365,0),5) -> 1 | D10: =DATEDIF(Assumptions!B5,B10,"m")+1 -> 1 | E10: =TEXT(B10,"ddd") -> Fri | F10: =IF(WEEKDAY(B10,2)>=6,Assumptions!B34,Assumptions!B35) -> 1 | G10: =IF(D10>=13,(1+Assumptions!B46)^(D10-12),1) -> 1 | H10: =H9*(1+IF(C10=1,Assumptions!B22,Assumptions!B23)) -> 16.511464 | I10: =ROUND(H10*F10,0) -> 17 | J10: =I10*Assumptions!B24 -> 10200 | K10: =K9*(1+Assumptions!B30) -> 13.175013 | L10: =ROUND(K10*F10,0) -> 13 | M10: =L10*Assumptions!B31 -> 3900 | N10: =J10+M10 -> 14100 | O10: =IF(DAY(B10)=1,Assumptions!B38*G10,0) -> 0 | P10: =IF(DAY(B10)=1,Assumptions!B39*G10,0) -> 0 | Q10: =IF(DAY(B10)=1,Assumptions!B40*G10,0) -> 0 | R10: =IF(DAY(B10)=1,Assumptions!B41*G10,0) -> 0 | S10: =IF(AND(DAY(B10)=1,D10>=13),Assumptions!B42*G10,0) -> 0 | T10: =IF(DAY(B10)=1,Assumptions!B43*G10,0) -> 0 | U10: =SUM(O10:T10) -> 0 | V10: =N10-U10 -> 14100 | W10: =W9+V10 -> -5147500 | X10: =IF(W10>=0,"YES","No") -> No
A11: 10 | B11: =B10+1 -> 46032 | C11: =MIN(ROUNDUP(A11/365,0),5) -> 1 | D11: =DATEDIF(Assumptions!B5,B11,"m")+1 -> 1 | E11: =TEXT(B11,"ddd") -> Sat | F11: =IF(WEEKDAY(B11,2)>=6,Assumptions!B34,Assumptions!B35) -> 0.6 | G11: =IF(D11>=13,(1+Assumptions!B46)^(D11-12),1) -> 1 | H11: =H10*(1+IF(C11=1,Assumptions!B22,Assumptions!B23)) -> 16.522209 | I11: =ROUND(H11*F11,0) -> 10 | J11: =I11*Assumptions!B24 -> 6000 | K11: =K10*(1+Assumptions!B30) -> 13.17932 | L11: =ROUND(K11*F11,0) -> 8 | M11: =L11*Assumptions!B31 -> 2400 | N11: =J11+M11 -> 8400 | O11: =IF(DAY(B11)=1,Assumptions!B38*G11,0) -> 0 | P11: =IF(DAY(B11)=1,Assumptions!B39*G11,0) -> 0 | Q11: =IF(DAY(B11)=1,Assumptions!B40*G11,0) -> 0 | R11: =IF(DAY(B11)=1,Assumptions!B41*G11,0) -> 0 | S11: =IF(AND(DAY(B11)=1,D11>=13),Assumptions!B42*G11,0) -> 0 | T11: =IF(DAY(B11)=1,Assumptions!B43*G11,0) -> 0 | U11: =SUM(O11:T11) -> 0 | V11: =N11-U11 -> 8400 | W11: =W10+V11 -> -5139100 | X11: =IF(W11>=0,"YES","No") -> No
A12: 11 | B12: =B11+1 -> 46033 | C12: =MIN(ROUNDUP(A12/365,0),5) -> 1 | D12: =DATEDIF(Assumptions!B5,B12,"m")+1 -> 1 | E12: =TEXT(B12,"ddd") -> Sun | F12: =IF(WEEKDAY(B12,2)>=6,Assumptions!B34,Assumptions!B35) -> 0.6 | G12: =IF(D12>=13,(1+Assumptions!B46)^(D12-12),1) -> 1 | H12: =H11*(1+IF(C12=1,Assumptions!B22,Assumptions!B23)) -> 16.532961 | I12: =ROUND(H12*F12,0) -> 10 | J12: =I12*Assumptions!B24 -> 6000 | K12: =K11*(1+Assumptions!B30) -> 13.183629 | L12: =ROUND(K12*F12,0) -> 8 | M12: =L12*Assumptions!B31 -> 2400 | N12: =J12+M12 -> 8400 | O12: =IF(DAY(B12)=1,Assumptions!B38*G12,0) -> 0 | P12: =IF(DAY(B12)=1,Assumptions!B39*G12,0) -> 0 | Q12: =IF(DAY(B12)=1,Assumptions!B40*G12,0) -> 0 | R12: =IF(DAY(B12)=1,Assumptions!B41*G12,0) -> 0 | S12: =IF(AND(DAY(B12)=1,D12>=13),Assumptions!B42*G12,0) -> 0 | T12: =IF(DAY(B12)=1,Assumptions!B43*G12,0) -> 0 | U12: =SUM(O12:T12) -> 0 | V12: =N12-U12 -> 8400 | W12: =W11+V12 -> -5130700 | X12: =IF(W12>=0,"YES","No") -> No
A13: 12 | B13: =B12+1 -> 46034 | C13: =MIN(ROUNDUP(A13/365,0),5) -> 1 | D13: =DATEDIF(Assumptions!B5,B13,"m")+1 -> 1 | E13: =TEXT(B13,"ddd") -> Mon | F13: =IF(WEEKDAY(B13,2)>=6,Assumptions!B34,Assumptions!B35) -> 1 | G13: =IF(D13>=13,(1+Assumptions!B46)^(D13-12),1) -> 1 | H13: =H12*(1+IF(C13=1,Assumptions!B22,Assumptions!B23)) -> 16.54372 | I13: =ROUND(H13*F13,0) -> 17 | J13: =I13*Assumptions!B24 -> 10200 | K13: =K12*(1+Assumptions!B30) -> 13.187939 | L13: =ROUND(K13*F13,0) -> 13 | M13: =L13*Assumptions!B31 -> 3900 | N13: =J13+M13 -> 14100 | O13: =IF(DAY(B13)=1,Assumptions!B38*G13,0) -> 0 | P13: =IF(DAY(B13)=1,Assumptions!B39*G13,0) -> 0 | Q13: =IF(DAY(B13)=1,Assumptions!B40*G13,0) -> 0 | R13: =IF(DAY(B13)=1,Assumptions!B41*G13,0) -> 0 | S13: =IF(AND(DAY(B13)=1,D13>=13),Assumptions!B42*G13,0) -> 0 | T13: =IF(DAY(B13)=1,Assumptions!B43*G13,0) -> 0 | U13: =SUM(O13:T13) -> 0 | V13: =N13-U13 -> 14100 | W13: =W12+V13 -> -5116600 | X13: =IF(W13>=0,"YES","No") -> No
A14: 13 | B14: =B13+1 -> 46035 | C14: =MIN(ROUNDUP(A14/365,0),5) -> 1 | D14: =DATEDIF(Assumptions!B5,B14,"m")+1 -> 1 | E14: =TEXT(B14,"ddd") -> Tue | F14: =IF(WEEKDAY(B14,2)>=6,Assumptions!B34,Assumptions!B35) -> 1 | G14: =IF(D14>=13,(1+Assumptions!B46)^(D14-12),1) -> 1 | H14: =H13*(1+IF(C14=1,Assumptions!B22,Assumptions!B23)) -> 16.554486 | I14: =ROUND(H14*F14,0) -> 17 | J14: =I14*Assumptions!B24 -> 10200 | K14: =K13*(1+Assumptions!B30) -> 13.192251 | L14: =ROUND(K14*F14,0) -> 13 | M14: =L14*Assumptions!B31 -> 3900 | N14: =J14+M14 -> 14100 | O14: =IF(DAY(B14)=1,Assumptions!B38*G14,0) -> 0 | P14: =IF(DAY(B14)=1,Assumptions!B39*G14,0) -> 0 | Q14: =IF(DAY(B14)=1,Assumptions!B40*G14,0) -> 0 | R14: =IF(DAY(B14)=1,Assumptions!B41*G14,0) -> 0 | S14: =IF(AND(DAY(B14)=1,D14>=13),Assumptions!B42*G14,0) -> 0 | T14: =IF(DAY(B14)=1,Assumptions!B43*G14,0) -> 0 | U14: =SUM(O14:T14) -> 0 | V14: =N14-U14 -> 14100 | W14: =W13+V14 -> -5102500 | X14: =IF(W14>=0,"YES","No") -> No
A15: 14 | B15: =B14+1 -> 46036 | C15: =MIN(ROUNDUP(A15/365,0),5) -> 1 | D15: =DATEDIF(Assumptions!B5,B15,"m")+1 -> 1 | E15: =TEXT(B15,"ddd") -> Wed | F15: =IF(WEEKDAY(B15,2)>=6,Assumptions!B34,Assumptions!B35) -> 1 | G15: =IF(D15>=13,(1+Assumptions!B46)^(D15-12),1) -> 1 | H15: =H14*(1+IF(C15=1,Assumptions!B22,Assumptions!B23)) -> 16.565259 | I15: =ROUND(H15*F15,0) -> 17 | J15: =I15*Assumptions!B24 -> 10200 | K15: =K14*(1+Assumptions!B30) -> 13.196564 | L15: =ROUND(K15*F15,0) -> 13 | M15: =L15*Assumptions!B31 -> 3900 | N15: =J15+M15 -> 14100 | O15: =IF(DAY(B15)=1,Assumptions!B38*G15,0) -> 0 | P15: =IF(DAY(B15)=1,Assumptions!B39*G15,0) -> 0 | Q15: =IF(DAY(B15)=1,Assumptions!B40*G15,0) -> 0 | R15: =IF(DAY(B15)=1,Assumptions!B41*G15,0) -> 0 | S15: =IF(AND(DAY(B15)=1,D15>=13),Assumptions!B42*G15,0) -> 0 | T15: =IF(DAY(B15)=1,Assumptions!B43*G15,0) -> 0 | U15: =SUM(O15:T15) -> 0 | V15: =N15-U15 -> 14100 | W15: =W14+V15 -> -5088400 | X15: =IF(W15>=0,"YES","No") -> No
A16: 15 | B16: =B15+1 -> 46037 | C16: =MIN(ROUNDUP(A16/365,0),5) -> 1 | D16: =DATEDIF(Assumptions!B5,B16,"m")+1 -> 1 | E16: =TEXT(B16,"ddd") -> Thu | F16: =IF(WEEKDAY(B16,2)>=6,Assumptions!B34,Assumptions!B35) -> 1 | G16: =IF(D16>=13,(1+Assumptions!B46)^(D16-12),1) -> 1 | H16: =H15*(1+IF(C16=1,Assumptions!B22,Assumptions!B23)) -> 16.576039 | I16: =ROUND(H16*F16,0) -> 17 | J16: =I16*Assumptions!B24 -> 10200 | K16: =K15*(1+Assumptions!B30) -> 13.200879 | L16: =ROUND(K16*F16,0) -> 13 | M16: =L16*Assumptions!B31 -> 3900 | N16: =J16+M16 -> 14100 | O16: =IF(DAY(B16)=1,Assumptions!B38*G16,0) -> 0 | P16: =IF(DAY(B16)=1,Assumptions!B39*G16,0) -> 0 | Q16: =IF(DAY(B16)=1,Assumptions!B40*G16,0) -> 0 | R16: =IF(DAY(B16)=1,Assumptions!B41*G16,0) -> 0 | S16: =IF(AND(DAY(B16)=1,D16>=13),Assumptions!B42*G16,0) -> 0 | T16: =IF(DAY(B16)=1,Assumptions!B43*G16,0) -> 0 | U16: =SUM(O16:T16) -> 0 | V16: =N16-U16 -> 14100 | W16: =W15+V16 -> -5074300 | X16: =IF(W16>=0,"YES","No") -> No
A17: 16 | B17: =B16+1 -> 46038 | C17: =MIN(ROUNDUP(A17/365,0),5) -> 1 | D17: =DATEDIF(Assumptions!B5,B17,"m")+1 -> 1 | E17: =TEXT(B17,"ddd") -> Fri | F17: =IF(WEEKDAY(B17,2)>=6,Assumptions!B34,Assumptions!B35) -> 1 | G17: =IF(D17>=13,(1+Assumptions!B46)^(D17-12),1) -> 1 | H17: =H16*(1+IF(C17=1,Assumptions!B22,Assumptions!B23)) -> 16.586826 | I17: =ROUND(H17*F17,0) -> 17 | J17: =I17*Assumptions!B24 -> 10200 | K17: =K16*(1+Assumptions!B30) -> 13.205194 | L17: =ROUND(K17*F17,0) -> 13 | M17: =L17*Assumptions!B31 -> 3900 | N17: =J17+M17 -> 14100 | O17: =IF(DAY(B17)=1,Assumptions!B38*G17,0) -> 0 | P17: =IF(DAY(B17)=1,Assumptions!B39*G17,0) -> 0 | Q17: =IF(DAY(B17)=1,Assumptions!B40*G17,0) -> 0 | R17: =IF(DAY(B17)=1,Assumptions!B41*G17,0) -> 0 | S17: =IF(AND(DAY(B17)=1,D17>=13),Assumptions!B42*G17,0) -> 0 | T17: =IF(DAY(B17)=1,Assumptions!B43*G17,0) -> 0 | U17: =SUM(O17:T17) -> 0 | V17: =N17-U17 -> 14100 | W17: =W16+V17 -> -5060200 | X17: =IF(W17>=0,"YES","No") -> No
A18: 17 | B18: =B17+1 -> 46039 | C18: =MIN(ROUNDUP(A18/365,0),5) -> 1 | D18: =DATEDIF(Assumptions!B5,B18,"m")+1 -> 1 | E18: =TEXT(B18,"ddd") -> Sat | F18: =IF(WEEKDAY(B18,2)>=6,Assumptions!B34,Assumptions!B35) -> 0.6 | G18: =IF(D18>=13,(1+Assumptions!B46)^(D18-12),1) -> 1 | H18: =H17*(1+IF(C18=1,Assumptions!B22,Assumptions!B23)) -> 16.59762 | I18: =ROUND(H18*F18,0) -> 10 | J18: =I18*Assumptions!B24 -> 6000 | K18: =K17*(1+Assumptions!B30) -> 13.209512 | L18: =ROUND(K18*F18,0) -> 8 | M18: =L18*Assumptions!B31 -> 2400 | N18: =J18+M18 -> 8400 | O18: =IF(DAY(B18)=1,Assumptions!B38*G18,0) -> 0 | P18: =IF(DAY(B18)=1,Assumptions!B39*G18,0) -> 0 | Q18: =IF(DAY(B18)=1,Assumptions!B40*G18,0) -> 0 | R18: =IF(DAY(B18)=1,Assumptions!B41*G18,0) -> 0 | S18: =IF(AND(DAY(B18)=1,D18>=13),Assumptions!B42*G18,0) -> 0 | T18: =IF(DAY(B18)=1,Assumptions!B43*G18,0) -> 0 | U18: =SUM(O18:T18) -> 0 | V18: =N18-U18 -> 8400 | W18: =W17+V18 -> -5051800 | X18: =IF(W18>=0,"YES","No") -> No
A19: 18 | B19: =B18+1 -> 46040 | C19: =MIN(ROUNDUP(A19/365,0),5) -> 1 | D19: =DATEDIF(Assumptions!B5,B19,"m")+1 -> 1 | E19: =TEXT(B19,"ddd") -> Sun | F19: =IF(WEEKDAY(B19,2)>=6,Assumptions!B34,Assumptions!B35) -> 0.6 | G19: =IF(D19>=13,(1+Assumptions!B46)^(D19-12),1) -> 1 | H19: =H18*(1+IF(C19=1,Assumptions!B22,Assumptions!B23)) -> 16.608421 | I19: =ROUND(H19*F19,0) -> 10 | J19: =I19*Assumptions!B24 -> 6000 | K19: =K18*(1+Assumptions!B30) -> 13.21383 | L19: =ROUND(K19*F19,0) -> 8 | M19: =L19*Assumptions!B31 -> 2400 | N19: =J19+M19 -> 8400 | O19: =IF(DAY(B19)=1,Assumptions!B38*G19,0) -> 0 | P19: =IF(DAY(B19)=1,Assumptions!B39*G19,0) -> 0 | Q19: =IF(DAY(B19)=1,Assumptions!B40*G19,0) -> 0 | R19: =IF(DAY(B19)=1,Assumptions!B41*G19,0) -> 0 | S19: =IF(AND(DAY(B19)=1,D19>=13),Assumptions!B42*G19,0) -> 0 | T19: =IF(DAY(B19)=1,Assumptions!B43*G19,0) -> 0 | U19: =SUM(O19:T19) -> 0 | V19: =N19-U19 -> 8400 | W19: =W18+V19 -> -5043400 | X19: =IF(W19>=0,"YES","No") -> No
A20: 19 | B20: =B19+1 -> 46041 | C20: =MIN(ROUNDUP(A20/365,0),5) -> 1 | D20: =DATEDIF(Assumptions!B5,B20,"m")+1 -> 1 | E20: =TEXT(B20,"ddd") -> Mon | F20: =IF(WEEKDAY(B20,2)>=6,Assumptions!B34,Assumptions!B35) -> 1 | G20: =IF(D20>=13,(1+Assumptions!B46)^(D20-12),1) -> 1 | H20: =H19*(1+IF(C20=1,Assumptions!B22,Assumptions!B23)) -> 16.619229 | I20: =ROUND(H20*F20,0) -> 17 | J20: =I20*Assumptions!B24 -> 10200 | K20: =K19*(1+Assumptions!B30) -> 13.21815 | L20: =ROUND(K20*F20,0) -> 13 | M20: =L20*Assumptions!B31 -> 3900 | N20: =J20+M20 -> 14100 | O20: =IF(DAY(B20)=1,Assumptions!B38*G20,0) -> 0 | P20: =IF(DAY(B20)=1,Assumptions!B39*G20,0) -> 0 | Q20: =IF(DAY(B20)=1,Assumptions!B40*G20,0) -> 0 | R20: =IF(DAY(B20)=1,Assumptions!B41*G20,0) -> 0 | S20: =IF(AND(DAY(B20)=1,D20>=13),Assumptions!B42*G20,0) -> 0 | T20: =IF(DAY(B20)=1,Assumptions!B43*G20,0) -> 0 | U20: =SUM(O20:T20) -> 0 | V20: =N20-U20 -> 14100 | W20: =W19+V20 -> -5029300 | X20: =IF(W20>=0,"YES","No") -> No
A21: 20 | B21: =B20+1 -> 46042 | C21: =MIN(ROUNDUP(A21/365,0),5) -> 1 | D21: =DATEDIF(Assumptions!B5,B21,"m")+1 -> 1 | E21: =TEXT(B21,"ddd") -> Tue | F21: =IF(WEEKDAY(B21,2)>=6,Assumptions!B34,Assumptions!B35) -> 1 | G21: =IF(D21>=13,(1+Assumptions!B46)^(D21-12),1) -> 1 | H21: =H20*(1+IF(C21=1,Assumptions!B22,Assumptions!B23)) -> 16.630044 | I21: =ROUND(H21*F21,0) -> 17 | J21: =I21*Assumptions!B24 -> 10200 | K21: =K20*(1+Assumptions!B30) -> 13.222472 | L21: =ROUND(K21*F21,0) -> 13 | M21: =L21*Assumptions!B31 -> 3900 | N21: =J21+M21 -> 14100 | O21: =IF(DAY(B21)=1,Assumptions!B38*G21,0) -> 0 | P21: =IF(DAY(B21)=1,Assumptions!B39*G21,0) -> 0 | Q21: =IF(DAY(B21)=1,Assumptions!B40*G21,0) -> 0 | R21: =IF(DAY(B21)=1,Assumptions!B41*G21,0) -> 0 | S21: =IF(AND(DAY(B21)=1,D21>=13),Assumptions!B42*G21,0) -> 0 | T21: =IF(DAY(B21)=1,Assumptions!B43*G21,0) -> 0 | U21: =SUM(O21:T21) -> 0 | V21: =N21-U21 -> 14100 | W21: =W20+V21 -> -5015200 | X21: =IF(W21>=0,"YES","No") -> No
A22: 21 | B22: =B21+1 -> 46043 | C22: =MIN(ROUNDUP(A22/365,0),5) -> 1 | D22: =DATEDIF(Assumptions!B5,B22,"m")+1 -> 1 | E22: =TEXT(B22,"ddd") -> Wed | F22: =IF(WEEKDAY(B22,2)>=6,Assumptions!B34,Assumptions!B35) -> 1 | G22: =IF(D22>=13,(1+Assumptions!B46)^(D22-12),1) -> 1 | H22: =H21*(1+IF(C22=1,Assumptions!B22,Assumptions!B23)) -> 16.640866 | I22: =ROUND(H22*F22,0) -> 17 | J22: =I22*Assumptions!B24 -> 10200 | K22: =K21*(1+Assumptions!B30) -> 13.226795 | L22: =ROUND(K22*F22,0) -> 13 | M22: =L22*Assumptions!B31 -> 3900 | N22: =J22+M22 -> 14100 | O22: =IF(DAY(B22)=1,Assumptions!B38*G22,0) -> 0 | P22: =IF(DAY(B22)=1,Assumptions!B39*G22,0) -> 0 | Q22: =IF(DAY(B22)=1,Assumptions!B40*G22,0) -> 0 | R22: =IF(DAY(B22)=1,Assumptions!B41*G22,0) -> 0 | S22: =IF(AND(DAY(B22)=1,D22>=13),Assumptions!B42*G22,0) -> 0 | T22: =IF(DAY(B22)=1,Assumptions!B43*G22,0) -> 0 | U22: =SUM(O22:T22) -> 0 | V22: =N22-U22 -> 14100 | W22: =W21+V22 -> -5001100 | X22: =IF(W22>=0,"YES","No") -> No
A23: 22 | B23: =B22+1 -> 46044 | C23: =MIN(ROUNDUP(A23/365,0),5) -> 1 | D23: =DATEDIF(Assumptions!B5,B23,"m")+1 -> 1 | E23: =TEXT(B23,"ddd") -> Thu | F23: =IF(WEEKDAY(B23,2)>=6,Assumptions!B34,Assumptions!B35) -> 1 | G23: =IF(D23>=13,(1+Assumptions!B46)^(D23-12),1) -> 1 | H23: =H22*(1+IF(C23=1,Assumptions!B22,Assumptions!B23)) -> 16.651695 | I23: =ROUND(H23*F23,0) -> 17 | J23: =I23*Assumptions!B24 -> 10200 | K23: =K22*(1+Assumptions!B30) -> 13.231119 | L23: =ROUND(K23*F23,0) -> 13 | M23: =L23*Assumptions!B31 -> 3900 | N23: =J23+M23 -> 14100 | O23: =IF(DAY(B23)=1,Assumptions!B38*G23,0) -> 0 | P23: =IF(DAY(B23)=1,Assumptions!B39*G23,0) -> 0 | Q23: =IF(DAY(B23)=1,Assumptions!B40*G23,0) -> 0 | R23: =IF(DAY(B23)=1,Assumptions!B41*G23,0) -> 0 | S23: =IF(AND(DAY(B23)=1,D23>=13),Assumptions!B42*G23,0) -> 0 | T23: =IF(DAY(B23)=1,Assumptions!B43*G23,0) -> 0 | U23: =SUM(O23:T23) -> 0 | V23: =N23-U23 -> 14100 | W23: =W22+V23 -> -4987000 | X23: =IF(W23>=0,"YES","No") -> No
A24: 23 | B24: =B23+1 -> 46045 | C24: =MIN(ROUNDUP(A24/365,0),5) -> 1 | D24: =DATEDIF(Assumptions!B5,B24,"m")+1 -> 1 | E24: =TEXT(B24,"ddd") -> Fri | F24: =IF(WEEKDAY(B24,2)>=6,Assumptions!B34,Assumptions!B35) -> 1 | G24: =IF(D24>=13,(1+Assumptions!B46)^(D24-12),1) -> 1 | H24: =H23*(1+IF(C24=1,Assumptions!B22,Assumptions!B23)) -> 16.662532 | I24: =ROUND(H24*F24,0) -> 17 | J24: =I24*Assumptions!B24 -> 10200 | K24: =K23*(1+Assumptions!B30) -> 13.235445 | L24: =ROUND(K24*F24,0) -> 13 | M24: =L24*Assumptions!B31 -> 3900 | N24: =J24+M24 -> 14100 | O24: =IF(DAY(B24)=1,Assumptions!B38*G24,0) -> 0 | P24: =IF(DAY(B24)=1,Assumptions!B39*G24,0) -> 0 | Q24: =IF(DAY(B24)=1,Assumptions!B40*G24,0) -> 0 | R24: =IF(DAY(B24)=1,Assumptions!B41*G24,0) -> 0 | S24: =IF(AND(DAY(B24)=1,D24>=13),Assumptions!B42*G24,0) -> 0 | T24: =IF(DAY(B24)=1,Assumptions!B43*G24,0) -> 0 | U24: =SUM(O24:T24) -> 0 | V24: =N24-U24 -> 14100 | W24: =W23+V24 -> -4972900 | X24: =IF(W24>=0,"YES","No") -> No
A25: 24 | B25: =B24+1 -> 46046 | C25: =MIN(ROUNDUP(A25/365,0),5) -> 1 | D25: =DATEDIF(Assumptions!B5,B25,"m")+1 -> 1 | E25: =TEXT(B25,"ddd") -> Sat | F25: =IF(WEEKDAY(B25,2)>=6,Assumptions!B34,Assumptions!B35) -> 0.6 | G25: =IF(D25>=13,(1+Assumptions!B46)^(D25-12),1) -> 1 | H25: =H24*(1+IF(C25=1,Assumptions!B22,Assumptions!B23)) -> 16.673375 | I25: =ROUND(H25*F25,0) -> 10 | J25: =I25*Assumptions!B24 -> 6000 | K25: =K24*(1+Assumptions!B30) -> 13.239772 | L25: =ROUND(K25*F25,0) -> 8 | M25: =L25*Assumptions!B31 -> 2400 | N25: =J25+M25 -> 8400 | O25: =IF(DAY(B25)=1,Assumptions!B38*G25,0) -> 0 | P25: =IF(DAY(B25)=1,Assumptions!B39*G25,0) -> 0 | Q25: =IF(DAY(B25)=1,Assumptions!B40*G25,0) -> 0 | R25: =IF(DAY(B25)=1,Assumptions!B41*G25,0) -> 0 | S25: =IF(AND(DAY(B25)=1,D25>=13),Assumptions!B42*G25,0) -> 0 | T25: =IF(DAY(B25)=1,Assumptions!B43*G25,0) -> 0 | U25: =SUM(O25:T25) -> 0 | V25: =N25-U25 -> 8400 | W25: =W24+V25 -> -4964500 | X25: =IF(W25>=0,"YES","No") -> No
A26: 25 | B26: =B25+1 -> 46047 | C26: =MIN(ROUNDUP(A26/365,0),5) -> 1 | D26: =DATEDIF(Assumptions!B5,B26,"m")+1 -> 1 | E26: =TEXT(B26,"ddd") -> Sun | F26: =IF(WEEKDAY(B26,2)>=6,Assumptions!B34,Assumptions!B35) -> 0.6 | G26: =IF(D26>=13,(1+Assumptions!B46)^(D26-12),1) -> 1 | H26: =H25*(1+IF(C26=1,Assumptions!B22,Assumptions!B23)) -> 16.684225 | I26: =ROUND(H26*F26,0) -> 10 | J26: =I26*Assumptions!B24 -> 6000 | K26: =K25*(1+Assumptions!B30) -> 13.244101 | L26: =ROUND(K26*F26,0) -> 8 | M26: =L26*Assumptions!B31 -> 2400 | N26: =J26+M26 -> 8400 | O26: =IF(DAY(B26)=1,Assumptions!B38*G26,0) -> 0 | P26: =IF(DAY(B26)=1,Assumptions!B39*G26,0) -> 0 | Q26: =IF(DAY(B26)=1,Assumptions!B40*G26,0) -> 0 | R26: =IF(DAY(B26)=1,Assumptions!B41*G26,0) -> 0 | S26: =IF(AND(DAY(B26)=1,D26>=13),Assumptions!B42*G26,0) -> 0 | T26: =IF(DAY(B26)=1,Assumptions!B43*G26,0) -> 0 | U26: =SUM(O26:T26) -> 0 | V26: =N26-U26 -> 8400 | W26: =W25+V26 -> -4956100 | X26: =IF(W26>=0,"YES","No") -> No
A27: 26 | B27: =B26+1 -> 46048 | C27: =MIN(ROUNDUP(A27/365,0),5) -> 1 | D27: =DATEDIF(Assumptions!B5,B27,"m")+1 -> 1 | E27: =TEXT(B27,"ddd") -> Mon | F27: =IF(WEEKDAY(B27,2)>=6,Assumptions!B34,Assumptions!B35) -> 1 | G27: =IF(D27>=13,(1+Assumptions!B46)^(D27-12),1) -> 1 | H27: =H26*(1+IF(C27=1,Assumptions!B22,Assumptions!B23)) -> 16.695083 | I27: =ROUND(H27*F27,0) -> 17 | J27: =I27*Assumptions!B24 -> 10200 | K27: =K26*(1+Assumptions!B30) -> 13.248431 | L27: =ROUND(K27*F27,0) -> 13 | M27: =L27*Assumptions!B31 -> 3900 | N27: =J27+M27 -> 14100 | O27: =IF(DAY(B27)=1,Assumptions!B38*G27,0) -> 0 | P27: =IF(DAY(B27)=1,Assumptions!B39*G27,0) -> 0 | Q27: =IF(DAY(B27)=1,Assumptions!B40*G27,0) -> 0 | R27: =IF(DAY(B27)=1,Assumptions!B41*G27,0) -> 0 | S27: =IF(AND(DAY(B27)=1,D27>=13),Assumptions!B42*G27,0) -> 0 | T27: =IF(DAY(B27)=1,Assumptions!B43*G27,0) -> 0 | U27: =SUM(O27:T27) -> 0 | V27: =N27-U27 -> 14100 | W27: =W26+V27 -> -4942000 | X27: =IF(W27>=0,"YES","No") -> No
A28: 27 | B28: =B27+1 -> 46049 | C28: =MIN(ROUNDUP(A28/365,0),5) -> 1 | D28: =DATEDIF(Assumptions!B5,B28,"m")+1 -> 1 | E28: =TEXT(B28,"ddd") -> Tue | F28: =IF(WEEKDAY(B28,2)>=6,Assumptions!B34,Assumptions!B35) -> 1 | G28: =IF(D28>=13,(1+Assumptions!B46)^(D28-12),1) -> 1 | H28: =H27*(1+IF(C28=1,Assumptions!B22,Assumptions!B23)) -> 16.705947 | I28: =ROUND(H28*F28,0) -> 17 | J28: =I28*Assumptions!B24 -> 10200 | K28: =K27*(1+Assumptions!B30) -> 13.252762 | L28: =ROUND(K28*F28,0) -> 13 | M28: =L28*Assumptions!B31 -> 3900 | N28: =J28+M28 -> 14100 | O28: =IF(DAY(B28)=1,Assumptions!B38*G28,0) -> 0 | P28: =IF(DAY(B28)=1,Assumptions!B39*G28,0) -> 0 | Q28: =IF(DAY(B28)=1,Assumptions!B40*G28,0) -> 0 | R28: =IF(DAY(B28)=1,Assumptions!B41*G28,0) -> 0 | S28: =IF(AND(DAY(B28)=1,D28>=13),Assumptions!B42*G28,0) -> 0 | T28: =IF(DAY(B28)=1,Assumptions!B43*G28,0) -> 0 | U28: =SUM(O28:T28) -> 0 | V28: =N28-U28 -> 14100 | W28: =W27+V28 -> -4927900 | X28: =IF(W28>=0,"YES","No") -> No
A29: 28 | B29: =B28+1 -> 46050 | C29: =MIN(ROUNDUP(A29/365,0),5) -> 1 | D29: =DATEDIF(Assumptions!B5,B29,"m")+1 -> 1 | E29: =TEXT(B29,"ddd") -> Wed | F29: =IF(WEEKDAY(B29,2)>=6,Assumptions!B34,Assumptions!B35) -> 1 | G29: =IF(D29>=13,(1+Assumptions!B46)^(D29-12),1) -> 1 | H29: =H28*(1+IF(C29=1,Assumptions!B22,Assumptions!B23)) -> 16.716819 | I29: =ROUND(H29*F29,0) -> 17 | J29: =I29*Assumptions!B24 -> 10200 | K29: =K28*(1+Assumptions!B30) -> 13.257095 | L29: =ROUND(K29*F29,0) -> 13 | M29: =L29*Assumptions!B31 -> 3900 | N29: =J29+M29 -> 14100 | O29: =IF(DAY(B29)=1,Assumptions!B38*G29,0) -> 0 | P29: =IF(DAY(B29)=1,Assumptions!B39*G29,0) -> 0 | Q29: =IF(DAY(B29)=1,Assumptions!B40*G29,0) -> 0 | R29: =IF(DAY(B29)=1,Assumptions!B41*G29,0) -> 0 | S29: =IF(AND(DAY(B29)=1,D29>=13),Assumptions!B42*G29,0) -> 0 | T29: =IF(DAY(B29)=1,Assumptions!B43*G29,0) -> 0 | U29: =SUM(O29:T29) -> 0 | V29: =N29-U29 -> 14100 | W29: =W28+V29 -> -4913800 | X29: =IF(W29>=0,"YES","No") -> No
A30: 29 | B30: =B29+1 -> 46051 | C30: =MIN(ROUNDUP(A30/365,0),5) -> 1 | D30: =DATEDIF(Assumptions!B5,B30,"m")+1 -> 1 | E30: =TEXT(B30,"ddd") -> Thu | F30: =IF(WEEKDAY(B30,2)>=6,Assumptions!B34,Assumptions!B35) -> 1 | G30: =IF(D30>=13,(1+Assumptions!B46)^(D30-12),1) -> 1 | H30: =H29*(1+IF(C30=1,Assumptions!B22,Assumptions!B23)) -> 16.727697 | I30: =ROUND(H30*F30,0) -> 17 | J30: =I30*Assumptions!B24 -> 10200 | K30: =K29*(1+Assumptions!B30) -> 13.261429 | L30: =ROUND(K30*F30,0) -> 13 | M30: =L30*Assumptions!B31 -> 3900 | N30: =J30+M30 -> 14100 | O30: =IF(DAY(B30)=1,Assumptions!B38*G30,0) -> 0 | P30: =IF(DAY(B30)=1,Assumptions!B39*G30,0) -> 0 | Q30: =IF(DAY(B30)=1,Assumptions!B40*G30,0) -> 0 | R30: =IF(DAY(B30)=1,Assumptions!B41*G30,0) -> 0 | S30: =IF(AND(DAY(B30)=1,D30>=13),Assumptions!B42*G30,0) -> 0 | T30: =IF(DAY(B30)=1,Assumptions!B43*G30,0) -> 0 | U30: =SUM(O30:T30) -> 0 | V30: =N30-U30 -> 14100 | W30: =W29+V30 -> -4899700 | X30: =IF(W30>=0,"YES","No") -> No
A31: 30 | B31: =B30+1 -> 46052 | C31: =MIN(ROUNDUP(A31/365,0),5) -> 1 | D31: =DATEDIF(Assumptions!B5,B31,"m")+1 -> 1 | E31: =TEXT(B31,"ddd") -> Fri | F31: =IF(WEEKDAY(B31,2)>=6,Assumptions!B34,Assumptions!B35) -> 1 | G31: =IF(D31>=13,(1+Assumptions!B46)^(D31-12),1) -> 1 | H31: =H30*(1+IF(C31=1,Assumptions!B22,Assumptions!B23)) -> 16.738583 | I31: =ROUND(H31*F31,0) -> 17 | J31: =I31*Assumptions!B24 -> 10200 | K31: =K30*(1+Assumptions!B30) -> 13.265765 | L31: =ROUND(K31*F31,0) -> 13 | M31: =L31*Assumptions!B31 -> 3900 | N31: =J31+M31 -> 14100 | O31: =IF(DAY(B31)=1,Assumptions!B38*G31,0) -> 0 | P31: =IF(DAY(B31)=1,Assumptions!B39*G31,0) -> 0 | Q31: =IF(DAY(B31)=1,Assumptions!B40*G31,0) -> 0 | R31: =IF(DAY(B31)=1,Assumptions!B41*G31,0) -> 0 | S31: =IF(AND(DAY(B31)=1,D31>=13),Assumptions!B42*G31,0) -> 0 | T31: =IF(DAY(B31)=1,Assumptions!B43*G31,0) -> 0 | U31: =SUM(O31:T31) -> 0 | V31: =N31-U31 -> 14100 | W31: =W30+V31 -> -4885600 | X31: =IF(W31>=0,"YES","No") -> No
A32: 31 | B32: =B31+1 -> 46053 | C32: =MIN(ROUNDUP(A32/365,0),5) -> 1 | D32: =DATEDIF(Assumptions!B5,B32,"m")+1 -> 1 | E32: =TEXT(B32,"ddd") -> Sat | F32: =IF(WEEKDAY(B32,2)>=6,Assumptions!B34,Assumptions!B35) -> 0.6 | G32: =IF(D32>=13,(1+Assumptions!B46)^(D32-12),1) -> 1 | H32: =H31*(1+IF(C32=1,Assumptions!B22,Assumptions!B23)) -> 16.749476 | I32: =ROUND(H32*F32,0) -> 10 | J32: =I32*Assumptions!B24 -> 6000 | K32: =K31*(1+Assumptions!B30) -> 13.270102 | L32: =ROUND(K32*F32,0) -> 8 | M32: =L32*Assumptions!B31 -> 2400 | N32: =J32+M32 -> 8400 | O32: =IF(DAY(B32)=1,Assumptions!B38*G32,0) -> 0 | P32: =IF(DAY(B32)=1,Assumptions!B39*G32,0) -> 0 | Q32: =IF(DAY(B32)=1,Assumptions!B40*G32,0) -> 0 | R32: =IF(DAY(B32)=1,Assumptions!B41*G32,0) -> 0 | S32: =IF(AND(DAY(B32)=1,D32>=13),Assumptions!B42*G32,0) -> 0 | T32: =IF(DAY(B32)=1,Assumptions!B43*G32,0) -> 0 | U32: =SUM(O32:T32) -> 0 | V32: =N32-U32 -> 8400 | W32: =W31+V32 -> -4877200 | X32: =IF(W32>=0,"YES","No") -> No
A33: 32 | B33: =B32+1 -> 46054 | C33: =MIN(ROUNDUP(A33/365,0),5) -> 1 | D33: =DATEDIF(Assumptions!B5,B33,"m")+1 -> 2 | E33: =TEXT(B33,"ddd") -> Sun | F33: =IF(WEEKDAY(B33,2)>=6,Assumptions!B34,Assumptions!B35) -> 0.6 | G33: =IF(D33>=13,(1+Assumptions!B46)^(D33-12),1) -> 1 | H33: =H32*(1+IF(C33=1,Assumptions!B22,Assumptions!B23)) -> 16.760375 | I33: =ROUND(H33*F33,0) -> 10 | J33: =I33*Assumptions!B24 -> 6000 | K33: =K32*(1+Assumptions!B30) -> 13.27444 | L33: =ROUND(K33*F33,0) -> 8 | M33: =L33*Assumptions!B31 -> 2400 | N33: =J33+M33 -> 8400 | O33: =IF(DAY(B33)=1,Assumptions!B38*G33,0) -> 150000 | P33: =IF(DAY(B33)=1,Assumptions!B39*G33,0) -> 40000 | Q33: =IF(DAY(B33)=1,Assumptions!B40*G33,0) -> 30000 | R33: =IF(DAY(B33)=1,Assumptions!B41*G33,0) -> 20000 | S33: =IF(AND(DAY(B33)=1,D33>=13),Assumptions!B42*G33,0) -> 0 | T33: =IF(DAY(B33)=1,Assumptions!B43*G33,0) -> 20000 | U33: =SUM(O33:T33) -> 260000 | V33: =N33-U33 -> -251600 | W33: =W32+V33 -> -5128800 | X33: =IF(W33>=0,"YES","No") -> No
A34: 33 | B34: =B33+1 -> 46055 | C34: =MIN(ROUNDUP(A34/365,0),5) -> 1 | D34: =DATEDIF(Assumptions!B5,B34,"m")+1 -> 2 | E34: =TEXT(B34,"ddd") -> Mon | F34: =IF(WEEKDAY(B34,2)>=6,Assumptions!B34,Assumptions!B35) -> 1 | G34: =IF(D34>=13,(1+Assumptions!B46)^(D34-12),1) -> 1 | H34: =H33*(1+IF(C34=1,Assumptions!B22,Assumptions!B23)) -> 16.771282 | I34: =ROUND(H34*F34,0) -> 17 | J34: =I34*Assumptions!B24 -> 10200 | K34: =K33*(1+Assumptions!B30) -> 13.27878 | L34: =ROUND(K34*F34,0) -> 13 | M34: =L34*Assumptions!B31 -> 3900 | N34: =J34+M34 -> 14100 | O34: =IF(DAY(B34)=1,Assumptions!B38*G34,0) -> 0 | P34: =IF(DAY(B34)=1,Assumptions!B39*G34,0) -> 0 | Q34: =IF(DAY(B34)=1,Assumptions!B40*G34,0) -> 0 | R34: =IF(DAY(B34)=1,Assumptions!B41*G34,0) -> 0 | S34: =IF(AND(DAY(B34)=1,D34>=13),Assumptions!B42*G34,0) -> 0 | T34: =IF(DAY(B34)=1,Assumptions!B43*G34,0) -> 0 | U34: =SUM(O34:T34) -> 0 | V34: =N34-U34 -> 14100 | W34: =W33+V34 -> -5114700 | X34: =IF(W34>=0,"YES","No") -> No
A35: 34 | B35: =B34+1 -> 46056 | C35: =MIN(ROUNDUP(A35/365,0),5) -> 1 | D35: =DATEDIF(Assumptions!B5,B35,"m")+1 -> 2 | E35: =TEXT(B35,"ddd") -> Tue | F35: =IF(WEEKDAY(B35,2)>=6,Assumptions!B34,Assumptions!B35) -> 1 | G35: =IF(D35>=13,(1+Assumptions!B46)^(D35-12),1) -> 1 | H35: =H34*(1+IF(C35=1,Assumptions!B22,Assumptions!B23)) -> 16.782196 | I35: =ROUND(H35*F35,0) -> 17 | J35: =I35*Assumptions!B24 -> 10200 | K35: =K34*(1+Assumptions!B30) -> 13.283121 | L35: =ROUND(K35*F35,0) -> 13 | M35: =L35*Assumptions!B31 -> 3900 | N35: =J35+M35 -> 14100 | O35: =IF(DAY(B35)=1,Assumptions!B38*G35,0) -> 0 | P35: =IF(DAY(B35)=1,Assumptions!B39*G35,0) -> 0 | Q35: =IF(DAY(B35)=1,Assumptions!B40*G35,0) -> 0 | R35: =IF(DAY(B35)=1,Assumptions!B41*G35,0) -> 0 | S35: =IF(AND(DAY(B35)=1,D35>=13),Assumptions!B42*G35,0) -> 0 | T35: =IF(DAY(B35)=1,Assumptions!B43*G35,0) -> 0 | U35: =SUM(O35:T35) -> 0 | V35: =N35-U35 -> 14100 | W35: =W34+V35 -> -5100600 | X35: =IF(W35>=0,"YES","No") -> No
A36: 35 | B36: =B35+1 -> 46057 | C36: =MIN(ROUNDUP(A36/365,0),5) -> 1 | D36: =DATEDIF(Assumptions!B5,B36,"m")+1 -> 2 | E36: =TEXT(B36,"ddd") -> Wed | F36: =IF(WEEKDAY(B36,2)>=6,Assumptions!B34,Assumptions!B35) -> 1 | G36: =IF(D36>=13,(1+Assumptions!B46)^(D36-12),1) -> 1 | H36: =H35*(1+IF(C36=1,Assumptions!B22,Assumptions!B23)) -> 16.793118 | I36: =ROUND(H36*F36,0) -> 17 | J36: =I36*Assumptions!B24 -> 10200 | K36: =K35*(1+Assumptions!B30) -> 13.287464 | L36: =ROUND(K36*F36,0) -> 13 | M36: =L36*Assumptions!B31 -> 3900 | N36: =J36+M36 -> 14100 | O36: =IF(DAY(B36)=1,Assumptions!B38*G36,0) -> 0 | P36: =IF(DAY(B36)=1,Assumptions!B39*G36,0) -> 0 | Q36: =IF(DAY(B36)=1,Assumptions!B40*G36,0) -> 0 | R36: =IF(DAY(B36)=1,Assumptions!B41*G36,0) -> 0 | S36: =IF(AND(DAY(B36)=1,D36>=13),Assumptions!B42*G36,0) -> 0 | T36: =IF(DAY(B36)=1,Assumptions!B43*G36,0) -> 0 | U36: =SUM(O36:T36) -> 0 | V36: =N36-U36 -> 14100 | W36: =W35+V36 -> -5086500 | X36: =IF(W36>=0,"YES","No") -> No
A37: 36 | B37: =B36+1 -> 46058 | C37: =MIN(ROUNDUP(A37/365,0),5) -> 1 | D37: =DATEDIF(Assumptions!B5,B37,"m")+1 -> 2 | E37: =TEXT(B37,"ddd") -> Thu | F37: =IF(WEEKDAY(B37,2)>=6,Assumptions!B34,Assumptions!B35) -> 1 | G37: =IF(D37>=13,(1+Assumptions!B46)^(D37-12),1) -> 1 | H37: =H36*(1+IF(C37=1,Assumptions!B22,Assumptions!B23)) -> 16.804046 | I37: =ROUND(H37*F37,0) -> 17 | J37: =I37*Assumptions!B24 -> 10200 | K37: =K36*(1+Assumptions!B30) -> 13.291808 | L37: =ROUND(K37*F37,0) -> 13 | M37: =L37*Assumptions!B31 -> 3900 | N37: =J37+M37 -> 14100 | O37: =IF(DAY(B37)=1,Assumptions!B38*G37,0) -> 0 | P37: =IF(DAY(B37)=1,Assumptions!B39*G37,0) -> 0 | Q37: =IF(DAY(B37)=1,Assumptions!B40*G37,0) -> 0 | R37: =IF(DAY(B37)=1,Assumptions!B41*G37,0) -> 0 | S37: =IF(AND(DAY(B37)=1,D37>=13),Assumptions!B42*G37,0) -> 0 | T37: =IF(DAY(B37)=1,Assumptions!B43*G37,0) -> 0 | U37: =SUM(O37:T37) -> 0 | V37: =N37-U37 -> 14100 | W37: =W36+V37 -> -5072400 | X37: =IF(W37>=0,"YES","No") -> No
A38: 37 | B38: =B37+1 -> 46059 | C38: =MIN(ROUNDUP(A38/365,0),5) -> 1 | D38: =DATEDIF(Assumptions!B5,B38,"m")+1 -> 2 | E38: =TEXT(B38,"ddd") -> Fri | F38: =IF(WEEKDAY(B38,2)>=6,Assumptions!B34,Assumptions!B35) -> 1 | G38: =IF(D38>=13,(1+Assumptions!B46)^(D38-12),1) -> 1 | H38: =H37*(1+IF(C38=1,Assumptions!B22,Assumptions!B23)) -> 16.814981 | I38: =ROUND(H38*F38,0) -> 17 | J38: =I38*Assumptions!B24 -> 10200 | K38: =K37*(1+Assumptions!B30) -> 13.296154 | L38: =ROUND(K38*F38,0) -> 13 | M38: =L38*Assumptions!B31 -> 3900 | N38: =J38+M38 -> 14100 | O38: =IF(DAY(B38)=1,Assumptions!B38*G38,0) -> 0 | P38: =IF(DAY(B38)=1,Assumptions!B39*G38,0) -> 0 | Q38: =IF(DAY(B38)=1,Assumptions!B40*G38,0) -> 0 | R38: =IF(DAY(B38)=1,Assumptions!B41*G38,0) -> 0 | S38: =IF(AND(DAY(B38)=1,D38>=13),Assumptions!B42*G38,0) -> 0 | T38: =IF(DAY(B38)=1,Assumptions!B43*G38,0) -> 0 | U38: =SUM(O38:T38) -> 0 | V38: =N38-U38 -> 14100 | W38: =W37+V38 -> -5058300 | X38: =IF(W38>=0,"YES","No") -> No
A39: 38 | B39: =B38+1 -> 46060 | C39: =MIN(ROUNDUP(A39/365,0),5) -> 1 | D39: =DATEDIF(Assumptions!B5,B39,"m")+1 -> 2 | E39: =TEXT(B39,"ddd") -> Sat | F39: =IF(WEEKDAY(B39,2)>=6,Assumptions!B34,Assumptions!B35) -> 0.6 | G39: =IF(D39>=13,(1+Assumptions!B46)^(D39-12),1) -> 1 | H39: =H38*(1+IF(C39=1,Assumptions!B22,Assumptions!B23)) -> 16.825924 | I39: =ROUND(H39*F39,0) -> 10 | J39: =I39*Assumptions!B24 -> 6000 | K39: =K38*(1+Assumptions!B30) -> 13.300501 | L39: =ROUND(K39*F39,0) -> 8 | M39: =L39*Assumptions!B31 -> 2400 | N39: =J39+M39 -> 8400 | O39: =IF(DAY(B39)=1,Assumptions!B38*G39,0) -> 0 | P39: =IF(DAY(B39)=1,Assumptions!B39*G39,0) -> 0 | Q39: =IF(DAY(B39)=1,Assumptions!B40*G39,0) -> 0 | R39: =IF(DAY(B39)=1,Assumptions!B41*G39,0) -> 0 | S39: =IF(AND(DAY(B39)=1,D39>=13),Assumptions!B42*G39,0) -> 0 | T39: =IF(DAY(B39)=1,Assumptions!B43*G39,0) -> 0 | U39: =SUM(O39:T39) -> 0 | V39: =N39-U39 -> 8400 | W39: =W38+V39 -> -5049900 | X39: =IF(W39>=0,"YES","No") -> No
A40: 39 | B40: =B39+1 -> 46061 | C40: =MIN(ROUNDUP(A40/365,0),5) -> 1 | D40: =DATEDIF(Assumptions!B5,B40,"m")+1 -> 2 | E40: =TEXT(B40,"ddd") -> Sun | F40: =IF(WEEKDAY(B40,2)>=6,Assumptions!B34,Assumptions!B35) -> 0.6 | G40: =IF(D40>=13,(1+Assumptions!B46)^(D40-12),1) -> 1 | H40: =H39*(1+IF(C40=1,Assumptions!B22,Assumptions!B23)) -> 16.836873 | I40: =ROUND(H40*F40,0) -> 10 | J40: =I40*Assumptions!B24 -> 6000 | K40: =K39*(1+Assumptions!B30) -> 13.304849 | L40: =ROUND(K40*F40,0) -> 8 | M40: =L40*Assumptions!B31 -> 2400 | N40: =J40+M40 -> 8400 | O40: =IF(DAY(B40)=1,Assumptions!B38*G40,0) -> 0 | P40: =IF(DAY(B40)=1,Assumptions!B39*G40,0) -> 0 | Q40: =IF(DAY(B40)=1,Assumptions!B40*G40,0) -> 0 | R40: =IF(DAY(B40)=1,Assumptions!B41*G40,0) -> 0 | S40: =IF(AND(DAY(B40)=1,D40>=13),Assumptions!B42*G40,0) -> 0 | T40: =IF(DAY(B40)=1,Assumptions!B43*G40,0) -> 0 | U40: =SUM(O40:T40) -> 0 | V40: =N40-U40 -> 8400 | W40: =W39+V40 -> -5041500 | X40: =IF(W40>=0,"YES","No") -> No
...

Sheet Monthly Summary
A1: Calendar Month # | B1: MM Transactions | C1: Commission Revenue | D1: Airtime Transactions | E1: Airtime Revenue | F1: Total Revenue | G1: Total Costs | H1: Net Profit | I1: Cumulative Net Cash Position (month-end)
A2: 1 | B2: =SUMIF('Daily Ledger'!$D$2:$D$1827,A2,'Daily Ledger'!$I$2:$I$1827) -> 459 | C2: =SUMIF('Daily Ledger'!$D$2:$D$1827,A2,'Daily Ledger'!$J$2:$J$1827) -> 275400 | D2: =SUMIF('Daily Ledger'!$D$2:$D$1827,A2,'Daily Ledger'!$L$2:$L$1827) -> 358 | E2: =SUMIF('Daily Ledger'!$D$2:$D$1827,A2,'Daily Ledger'!$M$2:$M$1827) -> 107400 | F2: =SUMIF('Daily Ledger'!$D$2:$D$1827,A2,'Daily Ledger'!$N$2:$N$1827) -> 382800 | G2: =SUMIF('Daily Ledger'!$D$2:$D$1827,A2,'Daily Ledger'!$U$2:$U$1827) -> 260000 | H2: =SUMIF('Daily Ledger'!$D$2:$D$1827,A2,'Daily Ledger'!$V$2:$V$1827) -> 122800 | I2: =LOOKUP(2,1/('Daily Ledger'!$D$2:$D$1827=A2),'Daily Ledger'!$W$2:$W$1827) -> -4877200
A3: 2 | B3: =SUMIF('Daily Ledger'!$D$2:$D$1827,A3,'Daily Ledger'!$I$2:$I$1827) -> 420 | C3: =SUMIF('Daily Ledger'!$D$2:$D$1827,A3,'Daily Ledger'!$J$2:$J$1827) -> 252000 | D3: =SUMIF('Daily Ledger'!$D$2:$D$1827,A3,'Daily Ledger'!$L$2:$L$1827) -> 324 | E3: =SUMIF('Daily Ledger'!$D$2:$D$1827,A3,'Daily Ledger'!$M$2:$M$1827) -> 97200 | F3: =SUMIF('Daily Ledger'!$D$2:$D$1827,A3,'Daily Ledger'!$N$2:$N$1827) -> 349200 | G3: =SUMIF('Daily Ledger'!$D$2:$D$1827,A3,'Daily Ledger'!$U$2:$U$1827) -> 260000 | H3: =SUMIF('Daily Ledger'!$D$2:$D$1827,A3,'Daily Ledger'!$V$2:$V$1827) -> 89200 | I3: =LOOKUP(2,1/('Daily Ledger'!$D$2:$D$1827=A3),'Daily Ledger'!$W$2:$W$1827) -> -4788000
A4: 3 | B4: =SUMIF('Daily Ledger'!$D$2:$D$1827,A4,'Daily Ledger'!$I$2:$I$1827) -> 464 | C4: =SUMIF('Daily Ledger'!$D$2:$D$1827,A4,'Daily Ledger'!$J$2:$J$1827) -> 278400 | D4: =SUMIF('Daily Ledger'!$D$2:$D$1827,A4,'Daily Ledger'!$L$2:$L$1827) -> 363 | E4: =SUMIF('Daily Ledger'!$D$2:$D$1827,A4,'Daily Ledger'!$M$2:$M$1827) -> 108900 | F4: =SUMIF('Daily Ledger'!$D$2:$D$1827,A4,'Daily Ledger'!$N$2:$N$1827) -> 387300 | G4: =SUMIF('Daily Ledger'!$D$2:$D$1827,A4,'Daily Ledger'!$U$2:$U$1827) -> 260000 | H4: =SUMIF('Daily Ledger'!$D$2:$D$1827,A4,'Daily Ledger'!$V$2:$V$1827) -> 127300 | I4: =LOOKUP(2,1/('Daily Ledger'!$D$2:$D$1827=A4),'Daily Ledger'!$W$2:$W$1827) -> -4660700
A5: 4 | B5: =SUMIF('Daily Ledger'!$D$2:$D$1827,A5,'Daily Ledger'!$I$2:$I$1827) -> 476 | C5: =SUMIF('Daily Ledger'!$D$2:$D$1827,A5,'Daily Ledger'!$J$2:$J$1827) -> 285600 | D5: =SUMIF('Daily Ledger'!$D$2:$D$1827,A5,'Daily Ledger'!$L$2:$L$1827) -> 372 | E5: =SUMIF('Daily Ledger'!$D$2:$D$1827,A5,'Daily Ledger'!$M$2:$M$1827) -> 111600 | F5: =SUMIF('Daily Ledger'!$D$2:$D$1827,A5,'Daily Ledger'!$N$2:$N$1827) -> 397200 | G5: =SUMIF('Daily Ledger'!$D$2:$D$1827,A5,'Daily Ledger'!$U$2:$U$1827) -> 260000 | H5: =SUMIF('Daily Ledger'!$D$2:$D$1827,A5,'Daily Ledger'!$V$2:$V$1827) -> 137200 | I5: =LOOKUP(2,1/('Daily Ledger'!$D$2:$D$1827=A5),'Daily Ledger'!$W$2:$W$1827) -> -4523500
A6: 5 | B6: =SUMIF('Daily Ledger'!$D$2:$D$1827,A6,'Daily Ledger'!$I$2:$I$1827) -> 488 | C6: =SUMIF('Daily Ledger'!$D$2:$D$1827,A6,'Daily Ledger'!$J$2:$J$1827) -> 292800 | D6: =SUMIF('Daily Ledger'!$D$2:$D$1827,A6,'Daily Ledger'!$L$2:$L$1827) -> 374 | E6: =SUMIF('Daily Ledger'!$D$2:$D$1827,A6,'Daily Ledger'!$M$2:$M$1827) -> 112200 | F6: =SUMIF('Daily Ledger'!$D$2:$D$1827,A6,'Daily Ledger'!$N$2:$N$1827) -> 405000 | G6: =SUMIF('Daily Ledger'!$D$2:$D$1827,A6,'Daily Ledger'!$U$2:$U$1827) -> 260000 | H6: =SUMIF('Daily Ledger'!$D$2:$D$1827,A6,'Daily Ledger'!$V$2:$V$1827) -> 145000 | I6: =LOOKUP(2,1/('Daily Ledger'!$D$2:$D$1827=A6),'Daily Ledger'!$W$2:$W$1827) -> -4378500
A7: 6 | B7: =SUMIF('Daily Ledger'!$D$2:$D$1827,A7,'Daily Ledger'!$I$2:$I$1827) -> 484 | C7: =SUMIF('Daily Ledger'!$D$2:$D$1827,A7,'Daily Ledger'!$J$2:$J$1827) -> 290400 | D7: =SUMIF('Daily Ledger'!$D$2:$D$1827,A7,'Daily Ledger'!$L$2:$L$1827) -> 372 | E7: =SUMIF('Daily Ledger'!$D$2:$D$1827,A7,'Daily Ledger'!$M$2:$M$1827) -> 111600 | F7: =SUMIF('Daily Ledger'!$D$2:$D$1827,A7,'Daily Ledger'!$N$2:$N$1827) -> 402000 | G7: =SUMIF('Daily Ledger'!$D$2:$D$1827,A7,'Daily Ledger'!$U$2:$U$1827) -> 260000 | H7: =SUMIF('Daily Ledger'!$D$2:$D$1827,A7,'Daily Ledger'!$V$2:$V$1827) -> 142000 | I7: =LOOKUP(2,1/('Daily Ledger'!$D$2:$D$1827=A7),'Daily Ledger'!$W$2:$W$1827) -> -4236500
A8: 7 | B8: =SUMIF('Daily Ledger'!$D$2:$D$1827,A8,'Daily Ledger'!$I$2:$I$1827) -> 523 | C8: =SUMIF('Daily Ledger'!$D$2:$D$1827,A8,'Daily Ledger'!$J$2:$J$1827) -> 313800 | D8: =SUMIF('Daily Ledger'!$D$2:$D$1827,A8,'Daily Ledger'!$L$2:$L$1827) -> 386 | E8: =SUMIF('Daily Ledger'!$D$2:$D$1827,A8,'Daily Ledger'!$M$2:$M$1827) -> 115800 | F8: =SUMIF('Daily Ledger'!$D$2:$D$1827,A8,'Daily Ledger'!$N$2:$N$1827) -> 429600 | G8: =SUMIF('Daily Ledger'!$D$2:$D$1827,A8,'Daily Ledger'!$U$2:$U$1827) -> 260000 | H8: =SUMIF('Daily Ledger'!$D$2:$D$1827,A8,'Daily Ledger'!$V$2:$V$1827) -> 169600 | I8: =LOOKUP(2,1/('Daily Ledger'!$D$2:$D$1827=A8),'Daily Ledger'!$W$2:$W$1827) -> -4066900
A9: 8 | B9: =SUMIF('Daily Ledger'!$D$2:$D$1827,A9,'Daily Ledger'!$I$2:$I$1827) -> 511 | C9: =SUMIF('Daily Ledger'!$D$2:$D$1827,A9,'Daily Ledger'!$J$2:$J$1827) -> 306600 | D9: =SUMIF('Daily Ledger'!$D$2:$D$1827,A9,'Daily Ledger'!$L$2:$L$1827) -> 378 | E9: =SUMIF('Daily Ledger'!$D$2:$D$1827,A9,'Daily Ledger'!$M$2:$M$1827) -> 113400 | F9: =SUMIF('Daily Ledger'!$D$2:$D$1827,A9,'Daily Ledger'!$N$2:$N$1827) -> 420000 | G9: =SUMIF('Daily Ledger'!$D$2:$D$1827,A9,'Daily Ledger'!$U$2:$U$1827) -> 260000 | H9: =SUMIF('Daily Ledger'!$D$2:$D$1827,A9,'Daily Ledger'!$V$2:$V$1827) -> 160000 | I9: =LOOKUP(2,1/('Daily Ledger'!$D$2:$D$1827=A9),'Daily Ledger'!$W$2:$W$1827) -> -3906900
A10: 9 | B10: =SUMIF('Daily Ledger'!$D$2:$D$1827,A10,'Daily Ledger'!$I$2:$I$1827) -> 521 | C10: =SUMIF('Daily Ledger'!$D$2:$D$1827,A10,'Daily Ledger'!$J$2:$J$1827) -> 312600 | D10: =SUMIF('Daily Ledger'!$D$2:$D$1827,A10,'Daily Ledger'!$L$2:$L$1827) -> 380 | E10: =SUMIF('Daily Ledger'!$D$2:$D$1827,A10,'Daily Ledger'!$M$2:$M$1827) -> 114000 | F10: =SUMIF('Daily Ledger'!$D$2:$D$1827,A10,'Daily Ledger'!$N$2:$N$1827) -> 426600 | G10: =SUMIF('Daily Ledger'!$D$2:$D$1827,A10,'Daily Ledger'!$U$2:$U$1827) -> 260000 | H10: =SUMIF('Daily Ledger'!$D$2:$D$1827,A10,'Daily Ledger'!$V$2:$V$1827) -> 166600 | I10: =LOOKUP(2,1/('Daily Ledger'!$D$2:$D$1827=A10),'Daily Ledger'!$W$2:$W$1827) -> -3740300
A11: 10 | B11: =SUMIF('Daily Ledger'!$D$2:$D$1827,A11,'Daily Ledger'!$I$2:$I$1827) -> 548 | C11: =SUMIF('Daily Ledger'!$D$2:$D$1827,A11,'Daily Ledger'!$J$2:$J$1827) -> 328800 | D11: =SUMIF('Daily Ledger'!$D$2:$D$1827,A11,'Daily Ledger'!$L$2:$L$1827) -> 390 | E11: =SUMIF('Daily Ledger'!$D$2:$D$1827,A11,'Daily Ledger'!$M$2:$M$1827) -> 117000 | F11: =SUMIF('Daily Ledger'!$D$2:$D$1827,A11,'Daily Ledger'!$N$2:$N$1827) -> 445800 | G11: =SUMIF('Daily Ledger'!$D$2:$D$1827,A11,'Daily Ledger'!$U$2:$U$1827) -> 260000 | H11: =SUMIF('Daily Ledger'!$D$2:$D$1827,A11,'Daily Ledger'!$V$2:$V$1827) -> 185800 | I11: =LOOKUP(2,1/('Daily Ledger'!$D$2:$D$1827=A11),'Daily Ledger'!$W$2:$W$1827) -> -3554500
A12: 11 | B12: =SUMIF('Daily Ledger'!$D$2:$D$1827,A12,'Daily Ledger'!$I$2:$I$1827) -> 528 | C12: =SUMIF('Daily Ledger'!$D$2:$D$1827,A12,'Daily Ledger'!$J$2:$J$1827) -> 316800 | D12: =SUMIF('Daily Ledger'!$D$2:$D$1827,A12,'Daily Ledger'!$L$2:$L$1827) -> 396 | E12: =SUMIF('Daily Ledger'!$D$2:$D$1827,A12,'Daily Ledger'!$M$2:$M$1827) -> 118800 | F12: =SUMIF('Daily Ledger'!$D$2:$D$1827,A12,'Daily Ledger'!$N$2:$N$1827) -> 435600 | G12: =SUMIF('Daily Ledger'!$D$2:$D$1827,A12,'Daily Ledger'!$U$2:$U$1827) -> 260000 | H12: =SUMIF('Daily Ledger'!$D$2:$D$1827,A12,'Daily Ledger'!$V$2:$V$1827) -> 175600 | I12: =LOOKUP(2,1/('Daily Ledger'!$D$2:$D$1827=A12),'Daily Ledger'!$W$2:$W$1827) -> -3378900
A13: 12 | B13: =SUMIF('Daily Ledger'!$D$2:$D$1827,A13,'Daily Ledger'!$I$2:$I$1827) -> 574 | C13: =SUMIF('Daily Ledger'!$D$2:$D$1827,A13,'Daily Ledger'!$J$2:$J$1827) -> 344400 | D13: =SUMIF('Daily Ledger'!$D$2:$D$1827,A13,'Daily Ledger'!$L$2:$L$1827) -> 417 | E13: =SUMIF('Daily Ledger'!$D$2:$D$1827,A13,'Daily Ledger'!$M$2:$M$1827) -> 125100 | F13: =SUMIF('Daily Ledger'!$D$2:$D$1827,A13,'Daily Ledger'!$N$2:$N$1827) -> 469500 | G13: =SUMIF('Daily Ledger'!$D$2:$D$1827,A13,'Daily Ledger'!$U$2:$U$1827) -> 260000 | H13: =SUMIF('Daily Ledger'!$D$2:$D$1827,A13,'Daily Ledger'!$V$2:$V$1827) -> 209500 | I13: =LOOKUP(2,1/('Daily Ledger'!$D$2:$D$1827=A13),'Daily Ledger'!$W$2:$W$1827) -> -3169400
... A61: 60 | B61: =SUMIF('Daily Ledger'!$D$2:$D$1827,A61,'Daily Ledger'!$I$2:$I$1827) -> 716 | C61: =SUMIF('Daily Ledger'!$D$2:$D$1827,A61,'Daily Ledger'!$J$2:$J$1827) -> 429600 | D61: =SUMIF('Daily Ledger'!$D$2:$D$1827,A61,'Daily Ledger'!$L$2:$L$1827) -> 654 | E61: =SUMIF('Daily Ledger'!$D$2:$D$1827,A61,'Daily Ledger'!$M$2:$M$1827) -> 196200 | F61: =SUMIF('Daily Ledger'!$D$2:$D$1827,A61,'Daily Ledger'!$N$2:$N$1827) -> 625800 | G61: =SUMIF('Daily Ledger'!$D$2:$D$1827,A61,'Daily Ledger'!$U$2:$U$1827) -> 473400.42 | H61: =SUMIF('Daily Ledger'!$D$2:$D$1827,A61,'Daily Ledger'!$V$2:$V$1827) -> 152399.58 | I61: =LOOKUP(2,1/('Daily Ledger'!$D$2:$D$1827=A61),'Daily Ledger'!$W$2:$W$1827) -> 1254025.2

Sheet Annual Summary
A1: Sim Year | B1: MM Transactions | C1: Commission Revenue | D1: Airtime Transactions | E1: Airtime Revenue | F1: Total Revenue | G1: Total Costs | H1: Net Profit | I1: Cumulative Net Cash Position (year-end)
A2: 1 | B2: =SUMIF('Daily Ledger'!$C$2:$C$1827,A2,'Daily Ledger'!$I$2:$I$1827) -> 5996 | C2: =SUMIF('Daily Ledger'!$C$2:$C$1827,A2,'Daily Ledger'!$J$2:$J$1827) -> 3597600 | D2: =SUMIF('Daily Ledger'!$C$2:$C$1827,A2,'Daily Ledger'!$L$2:$L$1827) -> 4510 | E2: =SUMIF('Daily Ledger'!$C$2:$C$1827,A2,'Daily Ledger'!$M$2:$M$1827) -> 1353000 | F2: =SUMIF('Daily Ledger'!$C$2:$C$1827,A2,'Daily Ledger'!$N$2:$N$1827) -> 4950600 | G2: =SUMIF('Daily Ledger'!$C$2:$C$1827,A2,'Daily Ledger'!$U$2:$U$1827) -> 3120000 | H2: =SUMIF('Daily Ledger'!$C$2:$C$1827,A2,'Daily Ledger'!$V$2:$V$1827) -> 1830600 | I2: =LOOKUP(2,1/('Daily Ledger'!$C$2:$C$1827=A2),'Daily Ledger'!$W$2:$W$1827) -> -3169400
A3: 2 | B3: =SUMIF('Daily Ledger'!$C$2:$C$1827,A3,'Daily Ledger'!$I$2:$I$1827) -> 6951 | C3: =SUMIF('Daily Ledger'!$C$2:$C$1827,A3,'Daily Ledger'!$J$2:$J$1827) -> 4170600 | D3: =SUMIF('Daily Ledger'!$C$2:$C$1827,A3,'Daily Ledger'!$L$2:$L$1827) -> 5080 | E3: =SUMIF('Daily Ledger'!$C$2:$C$1827,A3,'Daily Ledger'!$M$2:$M$1827) -> 1524000 | F3: =SUMIF('Daily Ledger'!$C$2:$C$1827,A3,'Daily Ledger'!$N$2:$N$1827) -> 5694600 | G3: =SUMIF('Daily Ledger'!$C$2:$C$1827,A3,'Daily Ledger'!$U$2:$U$1827) -> 5017003.3 | H3: =SUMIF('Daily Ledger'!$C$2:$C$1827,A3,'Daily Ledger'!$V$2:$V$1827) -> 677596.7 | I3: =LOOKUP(2,1/('Daily Ledger'!$C$2:$C$1827=A3),'Daily Ledger'!$W$2:$W$1827) -> -2491803.3
A4: 3 | B4: =SUMIF('Daily Ledger'!$C$2:$C$1827,A4,'Daily Ledger'!$I$2:$I$1827) -> 7340 | C4: =SUMIF('Daily Ledger'!$C$2:$C$1827,A4,'Daily Ledger'!$J$2:$J$1827) -> 4404000 | D4: =SUMIF('Daily Ledger'!$C$2:$C$1827,A4,'Daily Ledger'!$L$2:$L$1827) -> 5723 | E4: =SUMIF('Daily Ledger'!$C$2:$C$1827,A4,'Daily Ledger'!$M$2:$M$1827) -> 1716900 | F4: =SUMIF('Daily Ledger'!$C$2:$C$1827,A4,'Daily Ledger'!$N$2:$N$1827) -> 6120900 | G4: =SUMIF('Daily Ledger'!$C$2:$C$1827,A4,'Daily Ledger'!$U$2:$U$1827) -> 5200625.5 | H4: =SUMIF('Daily Ledger'!$C$2:$C$1827,A4,'Daily Ledger'!$V$2:$V$1827) -> 920274.48 | I4: =LOOKUP(2,1/('Daily Ledger'!$C$2:$C$1827=A4),'Daily Ledger'!$W$2:$W$1827) -> -1571528.8
A5: 4 | B5: =SUMIF('Daily Ledger'!$C$2:$C$1827,A5,'Daily Ledger'!$I$2:$I$1827) -> 7828 | C5: =SUMIF('Daily Ledger'!$C$2:$C$1827,A5,'Daily Ledger'!$J$2:$J$1827) -> 4696800 | D5: =SUMIF('Daily Ledger'!$C$2:$C$1827,A5,'Daily Ledger'!$L$2:$L$1827) -> 6448 | E5: =SUMIF('Daily Ledger'!$C$2:$C$1827,A5,'Daily Ledger'!$M$2:$M$1827) -> 1934400 | F5: =SUMIF('Daily Ledger'!$C$2:$C$1827,A5,'Daily Ledger'!$N$2:$N$1827) -> 6631200 | G5: =SUMIF('Daily Ledger'!$C$2:$C$1827,A5,'Daily Ledger'!$U$2:$U$1827) -> 5390968.3 | H5: =SUMIF('Daily Ledger'!$C$2:$C$1827,A5,'Daily Ledger'!$V$2:$V$1827) -> 1240231.7 | I5: =LOOKUP(2,1/('Daily Ledger'!$C$2:$C$1827=A5),'Daily Ledger'!$W$2:$W$1827) -> -331297.13
A6: 5 | B6: =SUMIF('Daily Ledger'!$C$2:$C$1827,A6,'Daily Ledger'!$I$2:$I$1827) -> 8309 | C6: =SUMIF('Daily Ledger'!$C$2:$C$1827,A6,'Daily Ledger'!$J$2:$J$1827) -> 4985400 | D6: =SUMIF('Daily Ledger'!$C$2:$C$1827,A6,'Daily Ledger'!$L$2:$L$1827) -> 7294 | E6: =SUMIF('Daily Ledger'!$C$2:$C$1827,A6,'Daily Ledger'!$M$2:$M$1827) -> 2188200 | F6: =SUMIF('Daily Ledger'!$C$2:$C$1827,A6,'Daily Ledger'!$N$2:$N$1827) -> 7173600 | G6: =SUMIF('Daily Ledger'!$C$2:$C$1827,A6,'Daily Ledger'!$U$2:$U$1827) -> 5588277.6 | H6: =SUMIF('Daily Ledger'!$C$2:$C$1827,A6,'Daily Ledger'!$V$2:$V$1827) -> 1585322.4 | I6: =LOOKUP(2,1/('Daily Ledger'!$C$2:$C$1827=A6),'Daily Ledger'!$W$2:$W$1827) -> 1254025.2
A7: TOTAL / 5-YR | B7: =SUM(B2:B6) -> 36424 | C7: =SUM(C2:C6) -> 21854400 | D7: =SUM(D2:D6) -> 29055 | E7: =SUM(E2:E6) -> 8716500 | F7: =SUM(F2:F6) -> 30570900 | G7: =SUM(G2:G6) -> 24316875 | H7: =SUM(H2:H6) -> 6254025.2 | I7: ='Daily Ledger'!W1827 -> 1254025.2

Sheet Break-Even Analysis
A1: Break-Even Analysis — Daily Model
A3: Total Initial Investment (Starting Capital) | B3: =Assumptions!B15 -> 5000000
A4: Average Net Daily Profit (Year 1) | B4: =AVERAGE('Daily Ledger'!V2:V366) -> 5015.3425
A5: Simple break-even (days), constant Year-1 average profit | B5: =B3/B4 -> 996.94089
A7: Break-even Day # (from cumulative cash position, dynamic model) | B7: =IFERROR(INDEX('Daily Ledger'!A2:A1827,MATCH(TRUE(),INDEX('Daily Ledger'!W2:W1827>=0,0),0)),"Not reached within simulation period") -> 1550
A8: Break-even Date | B8: =IFERROR(INDEX('Daily Ledger'!B2:B1827,MATCH(B7,'Daily Ledger'!A2:A1827,0)),"n/a") -> 47572
A9: Break-even Sim Year | B9: =ROUNDUP(B7/365,0) -> 5
A11: Interpretation
A12: The break-even point is the exact day on which the Cumulative Net Cash Position (Daily Ledger, column W) crosses from negative to zero/positive — the accumulated daily profit has fully repaid the starting capital in row 3. Every shilling of net profit from that day forward is clean profit for the investor.
